Workbook

Sheet Legende
A1: Dell Technologies Integration - Value Creation Integration Office (VCIO)
A2: Dell Inc. and EMC Corporation | Reporting week W3 (26 - 30 September 2016) | Day 22 after Day 1 | Close 7 September 2016
A4: How to use this workbook
A5: 1. Register Massnahmenplan: je Zeile eine Aufgabe. Fuehrende Quelle fuer Aufgaben und Termine nach Beschluss B-02.
A6: 2. Register Meilensteine: Basistermin bleibt nach Freigabe unveraendert. Verschiebungen laufen ueber den Prognosetermin, die Abweichung rechnet sich.
A7: 3. Register Beschlussregister und Massnahmenverfolgung: Beschluesse und offene Punkte aus VCIO Weekly und Steering Committee.
A8: 4. Register Abhaengigkeiten: jede Uebergabe zwischen Teilprojekten muss nach Beschluss B-03 von beiden Leitungen bestaetigt sein.
A9: 5. Register Auswertung rechnet automatisch. Formeln bitte nicht ueberschreiben.
A11: Conventions and assumptions
A12: Berichtswoche W3 (26 - 30 September 2016), Tag 22 nach Day 1 (07.09.2016). Day 100 ist der 16.12.2016.
A13: Datumsformat durchgaengig TT.MM.JJJJ. Fortschritt in Prozent als ganze Zahl.
A14: Sieben Teilprojekte berichten an das Steering Committee. Das Programm fuehrt insgesamt more than 20 Teilprojekte.
... A22: Synthetic workbook. All operational names, figures, risks and synergy values are invented and internally consistent; they are not a representation of what any party actually did.

Sheet Massnahmenplan
A1: Massnahmenplan (Master Task List)
A2: Stand 29.09.2016 | 38 Aufgaben | Verantwortlich: Value Creation Integration Office (VCIO)
A4: ID | B4: Aufgabe | C4: Teilprojekt | D4: Verantwortlich | E4: Faellig am | F4: Status | G4: Fortschritt % | H4: Prioritaet | I4: Abhaengig von | J4: Kommentar
A5: A-001 | B5: Kontenplan des Zielunternehmens auf den Konzernkontenplan abbilden | C5: WS1 Finanzen | D5: R. Whitfield | E5: 42646 | F5: In Arbeit | G5: 70 | H5: Hoch | J5: Map EMC chart of accounts to the Dell group chart
A6: A-002 | B6: Abschlusskalender beider Gruppen angleichen | C6: WS1 Finanzen | D6: R. Whitfield | E6: 42643 | F6: In Arbeit | G6: 85 | H6: Hoch | J6: Align statutory close calendar across both groups
A7: A-003 | B7: Konsolidierungskreis fuer das erste kombinierte Quartal festlegen | C7: WS1 Finanzen | D7: U. Hoffmeister | E7: 42657 | F7: Offen | G7: 20 | H7: Hoch | I7: A-012 | J7: Define consolidation scope for the first combined quarter
A8: A-004 | B8: Datenpaket zur Kaufpreisallokation erstellen | C8: WS1 Finanzen | D8: R. Whitfield | E8: 42641 | F8: Erledigt | G8: 100 | H8: Hoch | J8: Produce purchase price allocation input pack
A9: A-005 | B9: Konzerninterne Salden zum Stichtag abstimmen | C9: WS1 Finanzen | D9: U. Hoffmeister | E9: 42664 | F9: Offen | G9: 0 | H9: Mittel | I9: A-001 | J9: Reconcile intercompany balances at close date
A10: A-006 | B10: Zielmodell fuer Treasury und Cash Pooling entwerfen | C10: WS1 Finanzen | D10: R. Whitfield | E10: 42678 | F10: Offen | G10: 10 | H10: Mittel | J10: Draft treasury and cash pooling target model
A11: A-011 | B11: Steuerliche Pruefung der EMEA-Gesellschaftskette abschliessen | C11: WS2 Steuern | D11: N. Devereux | E11: 42650 | F11: Überfällig | G11: 55 | H11: Hoch | J11: Complete tax review of the EMEA entity chain
A12: A-012 | B12: Plan zur gesellschaftsrechtlichen Straffung zur Freigabe vorlegen | C12: WS2 Steuern | D12: N. Devereux | E12: 42655 | F12: Blockiert | G12: 40 | H12: Hoch | I12: A-011 | J12: Issue the legal entity rationalisation plan for approval
A13: A-013 | B13: Gliederung der Verrechnungspreisdokumentation entwerfen | C13: WS2 Steuern | D13: N. Devereux | E13: 42685 | F13: Offen | G13: 5 | H13: Mittel | I13: A-012 | J13: Draft transfer pricing documentation outline
A14: A-014 | B14: Betriebsstaettenrisiko in zwoelf Jurisdiktionen bewerten | C14: WS2 Steuern | D14: N. Devereux | E14: 42671 | F14: In Arbeit | G14: 30 | H14: Mittel | J14: Assess permanent establishment exposure in 12 jurisdictions
A15: A-021 | B15: Anwendungslandschaft beider Unternehmen vollstaendig erfassen | C15: WS3 IT | D15: T. Bergström | E15: 42636 | F15: Erledigt | G15: 100 | H15: Hoch | J15: Complete application landscape inventory for both estates
A16: A-022 | B16: Zielsystem und Migrationspfad fuer das ERP festlegen | C16: WS3 IT | D16: T. Bergström | E16: 42643 | F16: Überfällig | G16: 60 | H16: Hoch | I16: A-021 | J16: Agree the ERP target system and migration path
A17: A-023 | B17: Materialstammdaten mit korrigiertem Feldmapping erneut extrahieren | C17: WS3 IT | D17: G. Aydin | E17: 42648 | F17: In Arbeit | G17: 45 | H17: Hoch | I17: A-022 | J17: Re-extract material master with corrected field mapping
A18: A-024 | B18: Pilotgruppe auf die foederierte Anmeldung migrieren | C18: WS3 IT | D18: T. Bergström | E18: 42643 | F18: In Arbeit | G18: 80 | H18: Mittel | J18: Migrate pilot population to federated single sign-on
A19: A-025 | B19: Netzkopplung zwischen beiden Backbones herstellen | C19: WS3 IT | D19: T. Bergström | E19: 42657 | F19: In Arbeit | G19: 35 | H19: Hoch | J19: Complete network interconnect between the two backbones
A20: A-026 | B20: Service-Desk-Werkzeuge auf einer Plattform zusammenfuehren | C20: WS3 IT | D20: T. Bergström | E20: 42692 | F20: Offen | G20: 0 | H20: Niedrig | I20: A-025 | J20: Consolidate service desk tooling onto one platform
A21: A-031 | B21: Kombinierte Organisationsstruktur bis Ebene 3 veroeffentlichen | C21: WS4 Personal | D21: J. Adeyemi | E21: 42654 | F21: Blockiert | G21: 65 | H21: Hoch | I21: A-033 | J21: Publish combined organisation structure to level 3
A22: A-032 | B22: Verguetungsmodell im Vertrieb harmonisieren | C22: WS4 Personal | D22: J. Adeyemi | E22: 42654 | F22: In Arbeit | G22: 55 | H22: Hoch | J22: Harmonise sales compensation plan design
A23: A-033 | B23: Anhoerung des Betriebsrats in Deutschland abschliessen | C23: WS4 Personal | D23: W. Kempowski | E23: 42671 | F23: In Arbeit | G23: 40 | H23: Hoch | J23: Conclude works council consultation in Germany
A24: A-034 | B24: Halteprogramme fuer benannte Schluesselrollen bestaetigen | C24: WS4 Personal | D24: J. Adeyemi | E24: 42650 | F24: In Arbeit | G24: 75 | H24: Hoch | J24: Confirm retention packages for named critical roles
A25: A-035 | B25: Nutzung des Willkommens-eGuide bis Day 30 nachverfolgen | C25: WS4 Personal | D25: E. Brannigan | E25: 42650 | F25: In Arbeit | G25: 60 | H25: Mittel | J25: Track welcome eGuide adoption to Day 30
A26: A-036 | B26: Stellenarchitektur und Eingruppierung beider Gruppen angleichen | C26: WS4 Personal | D26: J. Adeyemi | E26: 42699 | F26: Offen | G26: 0 | H26: Mittel | I26: A-031 | J26: Align job architecture and grading across both groups
A27: A-041 | B27: Lieferantenstammdaten der 200 groessten Lieferanten bereinigen | C27: WS5 Lieferkette | D27: K. Matsuda | E27: 42648 | F27: In Arbeit | G27: 84 | H27: Hoch | J27: Cleanse supplier master for the top 200 vendors
A28: A-042 | B28: Beschaffungswuerfel fuer die Kategorien der Welle 1 aufbauen | C28: WS5 Lieferkette | D28: K. Matsuda | E28: 42657 | F28: In Arbeit | G28: 50 | H28: Hoch | I28: A-041 | J28: Build the combined spend cube for wave 1 categories
A29: A-043 | B29: Nachverhandlung mit den zwoelf groessten Logistikdienstleistern eroeffnen | C29: WS5 Lieferkette | D29: K. Matsuda | E29: 42671 | F29: Offen | G29: 15 | H29: Hoch | I29: A-042 | J29: Open renegotiation with the top 12 logistics providers
A30: A-044 | B30: Ueberschneidungen im Lagernetz in EMEA und APJ erfassen | C30: WS5 Lieferkette | D30: K. Matsuda | E30: 42685 | F30: Offen | G30: 0 | H30: Mittel | J30: Map warehouse footprint overlap in EMEA and APJ
A31: A-051 | B31: Produktportfolio-Konkordanz veroeffentlichen | C31: WS6 Vertrieb und Marketing | D31: L. Kowalczyk | E31: 42639 | F31: Erledigt | G31: 100 | H31: Hoch | J31: Publish combined product portfolio cross-reference
A32: A-052 | B32: Gebiets- und Quotenmodell fuer die kombinierte Vertriebsorganisation angleichen | C32: WS6 Vertrieb und Marketing | D32: L. Kowalczyk | E32: 42664 | F32: In Arbeit | G32: 40 | H32: Hoch | I32: A-032 | J32: Align territory and quota model for the merged field
A33: A-053 | B33: Kundenbotschaft fuer die Dell EMC World vorbereiten | C33: WS6 Vertrieb und Marketing | D33: E. Brannigan | E33: 42654 | F33: In Arbeit | G33: 55 | H33: Hoch | J33: Prepare the Dell EMC World customer narrative
A34: A-054 | B34: Konditionen der Partnerprogramme zusammenfuehren | C34: WS6 Vertrieb und Marketing | D34: L. Kowalczyk | E34: 42678 | F34: Offen | G34: 10 | H34: Mittel | J34: Consolidate partner programme terms
A35: A-055 | B35: Ausgangswert des Kunden-NPS erheben | C35: WS6 Vertrieb und Marketing | D35: S. Lindqvist | E35: 42657 | F35: In Arbeit | G35: 30 | H35: Mittel | J35: Measure customer net promoter score baseline
A36: A-061 | B36: Mietvertragsanalyse fuer 52 EMEA-Standorte abschliessen | C36: WS7 Immobilien | D36: F. Ricciardi | E36: 42664 | F36: In Arbeit | G36: 79 | H36: Mittel | J36: Complete lease expiry analysis for 52 EMEA sites
A37: A-062 | B37: Zusammenlegung der DACH-Hauptstandorte pruefen | C37: WS7 Immobilien | D37: H. Wegener | E37: 42678 | F37: Offen | G37: 20 | H37: Mittel | I37: A-061 | J37: Assess co-location options for the DACH head offices
A38: A-063 | B38: Beschilderung und Rebranding fuer Standorte der Stufe 1 terminieren | C38: WS7 Immobilien | D38: F. Ricciardi | E38: 42657 | F38: In Arbeit | G38: 45 | H38: Niedrig | J38: Confirm signage and rebranding schedule for tier 1 sites
A39: A-071 | B39: Bewertung im Wertpriorisierungsrahmen veroeffentlichen | C39: WS1 Finanzen | D39: M. Haddad | E39: 42636 | F39: Erledigt | G39: 100 | H39: Hoch | J39: Publish the value prioritisation framework scoring
A40: A-072 | B40: Synergieinitiativen der Welle 1 mit Finance validieren | C40: WS1 Finanzen | D40: M. Haddad | E40: 42650 | F40: In Arbeit | G40: 65 | H40: Hoch | J40: Validate synergy wave 1 initiatives with Finance
A41: A-073 | B41: Abhaengigkeitskarte zwischen den Teilprojekten aktualisieren | C41: WS3 IT | D41: D. Okonjo | E41: 42643 | F41: In Arbeit | G41: 90 | H41: Hoch | J41: Refresh the cross-workstream dependency map
...

Sheet Meilensteine
A1: Meilensteinplan (Milestone Plan)
A2: Day 1 07.09.2016 | Day 30 07.10.2016 | Day 100 16.12.2016 | 13 von 18 gate-relevant
A4: ID | B4: Meilenstein | C4: Phase | D4: Teilprojekt | E4: Verantwortlich | F4: Basistermin | G4: Prognosetermin | H4: Abweichung (Tage) | I4: Status | J4: Gate-relevant | K4: Kommentar
A5: M-01 | B5: Day 1 Vollzug und Markenauftritt umgesetzt | C5: Day 1 | D5: WS6 Vertrieb und Marketing | E5: L. Kowalczyk | F5: 42620 | G5: 42620 | H5: =G5-F5 -> 0 | I5: Erledigt | J5: Ja | K5: Closed on schedule. New Dell Technologies and Dell EMC branding launched the same day.
A6: M-02 | B6: Willkommens-eGuide zu Day 1 fuer alle 140.000 Mitarbeitenden verfuegbar | C6: Day 1 | D6: WS4 Personal | E6: J. Adeyemi | F6: 42620 | G6: 42620 | H6: =G6-F6 -> 0 | I6: Erledigt | J6: Ja | K6: Digital tool delivered with advisory support. Adoption tracking continues to Day 30.
A7: M-03 | B7: Vertriebs-Runbook fuer ueber 40.000 Vertriebsmitarbeitende verfuegbar | C7: Day 1 | D7: WS6 Vertrieb und Marketing | E7: L. Kowalczyk | F7: 42620 | G7: 42620 | H7: =G7-F7 -> 0 | I7: Erledigt | J7: Ja | K7: Cross-sell guidance for the combined portfolio available at close.
A8: M-04 | B8: Kombinierte Eroeffnungsbilanz erstellt | C8: Day 1 to Day 30 | D8: WS1 Finanzen | E8: R. Whitfield | F8: 42650 | G8: 42650 | H8: =G8-F8 -> 0 | I8: Im Plan | J8: Ja | K8: Purchase price allocation input from valuation advisor received on schedule.
A9: M-05 | B9: Plan zur Gesellschaftsrechtlichen Straffung freigegeben | C9: Day 1 to Day 30 | D9: WS2 Steuern | E9: N. Devereux | F9: 42650 | G9: 42657 | H9: =G9-F9 -> 7 | I9: Verzögert | J9: Ja | K9: Slipped one week. Tax review of the EMEA entity chain is not complete.
A10: M-06 | B10: Vorlaeufiges Konzernberichtspaket erstellt | C10: Day 1 to Day 30 | D10: WS1 Finanzen | E10: R. Whitfield | F10: 42650 | G10: 42650 | H10: =G10-F10 -> 0 | I10: Im Plan | J10: Nein | K10: First combined management pack for the sponsor.
A11: M-07 | B11: Zielbild ERP-Konsolidierung freigegeben | C11: Day 1 to Day 30 | D11: WS3 IT | E11: T. Bergström | F11: 42650 | G11: 42664 | H11: =G11-F11 -> 14 | I11: Verzögert | J11: Ja | K11: Two weeks late. Legacy ERP upgrade at the target ran into the integration design. See escalation thread and expert session record.
A12: M-08 | B12: Einheitliche Anmeldung und Verzeichnisfoederation aktiv | C12: Day 1 to Day 30 | D12: WS3 IT | E12: T. Bergström | F12: 42650 | G12: 42650 | H12: =G12-F12 -> 0 | I12: Im Plan | J12: Nein | K12: Pilot population migrated, full cutover on plan.
A13: M-09 | B13: Harmonisiertes Verguetungsmodell Vertrieb kommuniziert | C13: Day 1 to Day 30 | D13: WS4 Personal | E13: J. Adeyemi | F13: 42650 | G13: 42654 | H13: =G13-F13 -> 4 | I13: Gefährdet | J13: Ja | K13: Depends on works council consultation in DACH concluding first.
A14: M-10 | B14: Lieferantenstammdaten fuer die 200 groessten Lieferanten konsolidiert | C14: Day 1 to Day 30 | D14: WS5 Lieferkette | E14: K. Matsuda | F14: 42650 | G14: 42650 | H14: =G14-F14 -> 0 | I14: Im Plan | J14: Nein | K14: Data cleanse complete for 168 of 200 vendors.
A15: M-11 | B15: Kombiniertes Portfolio auf der Dell EMC World praesentiert | C15: Day 30 to Day 100 | D15: WS6 Vertrieb und Marketing | E15: L. Kowalczyk | F15: 42661 | G15: 42661 | H15: =G15-F15 -> 0 | I15: Im Plan | J15: Ja | K15: Fixed external date, 18 to 20 October, Austin. Cannot move.
A16: M-12 | B16: Kundenbetreuungsmodell fuer die kombinierte Vertriebsorganisation in Kraft | C16: Day 30 to Day 100 | D16: WS6 Vertrieb und Marketing | E16: L. Kowalczyk | F16: 42678 | G16: 42678 | H16: =G16-F16 -> 0 | I16: Im Plan | J16: Ja | K16: Territory and quota alignment for the merged field organisation.
... A22: M-18 | B22: Integrationsorganisation in den Regelbetrieb ueberfuehrt | C22: Post Day 100 | D22: WS4 Personal | E22: D. Okonjo | F22: 42720 | G22: 42720 | H22: =G22-F22 -> 0 | I22: Im Plan | J22: Nein | K22: Handover of open items to functional owners.

Sheet Beschlussregister
A1: Beschlussregister (Decision Log)
A2: Beschluesse aus VCIO Weekly und Steering Committee, Stand 29.09.2016
A4: ID | B4: Beschluss | C4: Begruendung | D4: Gremium | E4: Datum | F4: Betroffene Teilprojekte | G4: Umsetzung durch | H4: Umsetzungsstand
A5: B-01 | B5: Den Wertpriorisierungsrahmen als alleinige Grundlage fuer die Reihenfolge der Integrationsarbeit einfuehren | C5: Focus the office on the fifth of the opportunities that carries most of the accretive value, seen through a customer-first lens | D5: Steering Committee | E5: 42628 | F5: all | G5: A. Vasquez | H5: Implemented
A6: B-02 | B6: Den Integration Tracker als alleinige Quelle fuer Aufgaben, Meilensteine und Termine verbindlich setzen | C6: Six reporting formats were reaching the office and reconciliation was consuming the analyst capacity intended for analysis | D6: Steering Committee | E6: 42628 | F6: all | G6: S. Lindqvist | H6: In progress
A7: B-03 | B7: Jeden Uebergabetermin zwischen Teilprojekten von beiden Teilprojektleitungen im Abhaengigkeitsregister bestaetigen lassen | C7: Teams understand their own responsibilities but not how their activities land on others; unconfirmed handovers were the largest single source of slippage | D7: Steering Committee | E7: 42628 | F7: all | G7: D. Okonjo | H7: In progress
A8: B-04 | B8: Den Umfang der laufenden ERP-Modernisierung beim Zielunternehmen einfrieren, bis das Zielbild der Konsolidierung freigegeben ist | C8: The upgrade and the integration design were competing for the same architecture decisions and the same people | D8: VCIO | E8: 42634 | F8: WS3, WS1, WS5 | G8: T. Bergström | H8: In progress
A9: B-05 | B9: Mitbestimmte Einheiten aus der ersten Organisationsankuendigung ausnehmen | C9: German consultation is a legal gate, not a communication preference; announcing before it concludes would create a compliance exposure | D9: VCIO | E9: 42640 | F9: WS4 | G9: W. Kempowski | H9: Open
A10: B-06 | B10: Nur von Finance validierte Initiativen als gesicherte Synergie ausweisen | C10: Reported secured value was running ahead of what the baseline could support | D10: Steering Committee | E10: 42628 | F10: all | G10: M. Haddad | H10: Implemented
A11: B-07 | B11: Den Termin des Wertrealisierungsberichts zu Day 100 halten und stattdessen den Umfang neu takten | C11: The date is a sponsor commitment; scope is the variable that can move | D11: Steering Committee | E11: 42642 | F11: all | G11: A. Vasquez | H11: Open
A12: B-08 | B12: Bis zum Inkrafttreten des Betreuungsmodells woechentlich eine vorlaeufige Kundenzuordnung veroeffentlichen | C12: Two field organisations were calling on the same accounts | D12: VCIO | E12: 42633 | F12: WS6 | G12: L. Kowalczyk | H12: Implemented

Sheet Massnahmenverfolgung
A1: Massnahmenverfolgung (Action Item Log)
A2: Offene Punkte aus Sitzungen, Stand 29.09.2016 | 2 von 12 geschlossen, 2 verschoben
A4: Nr. | B4: Offener Punkt | C4: Quelle | D4: Verantwortlich | E4: Teilprojekt | F4: Urspruenglich faellig | G4: Neuer Termin | H4: Verschiebungen | I4: Status
A5: OP-01 | B5: Die aktualisierte Abhaengigkeitskarte an alle Teilprojektleitungen versenden | C5: SteerCo session 01, 15 September 2016 | D5: D. Okonjo | E5: WS3 | F5: 42636 | G5: 42643 | H5: 1 | I5: In Arbeit
A6: OP-02 | B6: Wiederanlaufplan fuer das ERP-Zielbild mit datierter Prognose vorlegen | C6: SteerCo session 01, 15 September 2016 | D6: T. Bergström | E6: WS3 | F6: 42642 | G6: 42642 | H6: 0 | I6: In Arbeit
A7: OP-03 | B7: Den Zeitplan der Betriebsratsanhoerung schriftlich bestaetigen | C7: SteerCo session 01, 15 September 2016 | D7: W. Kempowski | E7: WS4 | F7: 42643 | G7: 42643 | H7: 0 | I7: In Arbeit
A8: OP-04 | B8: Die berichtete gesicherte Synergie auf den von Finance validierten Wert abstimmen | C8: SteerCo session 01, 15 September 2016 | D8: M. Haddad | E8: WS1 | F8: 42641 | G8: 42641 | H8: 0 | I8: Erledigt
A9: OP-05 | B9: Die steuerliche Pruefung der EMEA-Gesellschaftskette eskalieren und einen Abschlusstermin benennen | C9: IMO weekly, 27 September 2016 | D9: N. Devereux | E9: WS2 | F9: 42646 | G9: 42646 | H9: 0 | I9: Offen
A10: OP-06 | B10: Vor jeder Migrationswelle ein Datenqualitaetstor einziehen | C10: Expert session, 21 September 2016 | D10: G. Aydin | E10: WS3 | F10: 42648 | G10: 42648 | H10: 0 | I10: In Arbeit
A11: OP-07 | B11: Die Kommunikation des Betreuungsmodells um zwei Wochen vorziehen | C11: IMO weekly, 27 September 2016 | D11: L. Kowalczyk | E11: WS6 | F11: 42650 | G11: 42650 | H11: 0 | I11: Offen
A12: OP-08 | B12: Die Tabelle der Rolleninhaber nach dem Wechsel der Teilprojektleitung Personal aktualisieren | C12: IMO weekly, 20 September 2016 | D12: D. Okonjo | E12: WS4 | F12: 42636 | G12: 42643 | H12: 1 | I12: In Arbeit
A13: OP-09 | B13: Die versicherungsmathematische Pruefung der Pensionsverpflichtung beauftragen | C13: WS1 jour fixe, 27 September 2016 | D13: R. Whitfield | E13: WS1 | F13: 42646 | G13: 42646 | H13: 0 | I13: Offen
A14: OP-10 | B14: Die vorlaeufige Kundenzuordnung erstmals veroeffentlichen | C14: VCIO decision B-08, 20 September 2016 | D14: L. Kowalczyk | E14: WS6 | F14: 42639 | G14: 42639 | H14: 0 | I14: Erledigt
A15: OP-11 | B15: Umsetzungskosten fuer Initiativen ausserhalb des kritischen Pfades neu takten | C15: IMO weekly, 27 September 2016 | D15: R. Whitfield | E15: WS1 | F15: 42657 | G15: 42657 | H15: 0 | I15: Offen
A16: OP-12 | B16: Den Vertrieb vor der Leitveranstaltung zur Portfolio-Konkordanz briefen | C16: IMO weekly, 27 September 2016 | D16: E. Brannigan | E16: WS6 | F16: 42650 | G16: 42650 | H16: 0 | I16: In Arbeit

Sheet Abhaengigkeiten
A1: Abhaengigkeitsregister (Dependency Register)
A2: Uebergaben zwischen Teilprojekten | Beschluss B-03 verlangt Bestaetigung durch beide Leitungen | 2 offen
A4: ID | B4: Uebergabe | C4: Von Teilprojekt | D4: An Teilprojekt | E4: Benoetigt bis | F4: Kritikalitaet | G4: Von beiden bestaetigt | H4: Status
A5: D-01 | B5: Approved legal entity structure required to fix the consolidation scope | C5: WS2 Steuern | D5: WS1 Finanzen | E5: 42655 | F5: Critical | G5: Nein | H5: At risk
A6: D-02 | B6: ERP target system decision required before the material master re-extract | C6: WS3 IT | D6: WS5 Lieferkette | E6: 42646 | F6: Critical | G6: Ja | H6: Delayed
A7: D-03 | B7: Works council conclusion required before the organisation structure release | C7: WS4 Personal | D7: WS4 Personal | E7: 42671 | F7: Critical | G7: Ja | H7: At risk
A8: D-04 | B8: Compensation plan design required before territory and quota alignment | C8: WS4 Personal | D8: WS6 Vertrieb und Marketing | E8: 42654 | F8: High | G8: Ja | H8: On track
A9: D-05 | B9: Spend cube required before logistics renegotiation can be scoped | C9: WS5 Lieferkette | D9: WS5 Lieferkette | E9: 42657 | F9: High | G9: Ja | H9: On track
A10: D-06 | B10: Lease expiry analysis required before the EMEA site plan is approved | C10: WS7 Immobilien | D10: WS7 Immobilien | E10: 42664 | F10: Medium | G10: Ja | H10: On track
A11: D-07 | B11: Entity plan required before transfer pricing documentation can begin | C11: WS2 Steuern | D11: WS2 Steuern | E11: 42655 | F11: High | G11: Nein | H11: At risk
A12: D-08 | B12: Portfolio cross-reference required before the flagship event narrative | C12: WS6 Vertrieb und Marketing | D12: WS6 Vertrieb und Marketing | E12: 42654 | F12: High | G12: Ja | H12: On track

Sheet Auswertung
A1: Auswertung (Summary)
A2: Rechnet automatisch aus den Registern Massnahmenplan und Meilensteine. Keine Eingabe.
A4: Aufgaben nach Status
A5: Status | B5: Anzahl | C5: Anteil
A6: Offen | B6: =COUNTIF(Massnahmenplan!$F$5:$F$42,$A6) -> 10 | C6: =IFERROR($B6/$B$11,"") -> 0.26315789
A7: In Arbeit | B7: =COUNTIF(Massnahmenplan!$F$5:$F$42,$A7) -> 20 | C7: =IFERROR($B7/$B$11,"") -> 0.52631579
A8: Erledigt | B8: =COUNTIF(Massnahmenplan!$F$5:$F$42,$A8) -> 4 | C8: =IFERROR($B8/$B$11,"") -> 0.10526316
A9: Blockiert | B9: =COUNTIF(Massnahmenplan!$F$5:$F$42,$A9) -> 2 | C9: =IFERROR($B9/$B$11,"") -> 0.052631579
A10: Überfällig | B10: =COUNTIF(Massnahmenplan!$F$5:$F$42,$A10) -> 2 | C10: =IFERROR($B10/$B$11,"") -> 0.052631579
A11: Summe | B11: =SUM($B$6:$B$10) -> 38
A13: Je Teilprojekt
A14: Teilprojekt | B14: Aufgaben | C14: davon erledigt | D14: davon ueberfaellig | E14: Fortschritt % | F14: Meilensteine | G14: davon verzoegert
A15: WS1 Finanzen | B15: =COUNTIF(Massnahmenplan!$C$5:$C$42,$A15) -> 9 | C15: =COUNTIFS(Massnahmenplan!$C$5:$C$42,$A15,Massnahmenplan!$F$5:$F$42,"Erledigt") -> 2 | D15: =COUNTIFS(Massnahmenplan!$C$5:$C$42,$A15,Massnahmenplan!$F$5:$F$42,"Überfällig") -> 0 | E15: =IFERROR(ROUND(AVERAGEIF(Massnahmenplan!$C$5:$C$42,$A15,Massnahmenplan!$G$5:$G$42),0),"") -> 57 | F15: =COUNTIF(Meilensteine!$D$5:$D$22,$A15) -> 3 | G15: =COUNTIFS(Meilensteine!$D$5:$D$22,$A15,Meilensteine!$I$5:$I$22,"Verzögert") -> 0
A16: WS2 Steuern | B16: =COUNTIF(Massnahmenplan!$C$5:$C$42,$A16) -> 4 | C16: =COUNTIFS(Massnahmenplan!$C$5:$C$42,$A16,Massnahmenplan!$F$5:$F$42,"Erledigt") -> 0 | D16: =COUNTIFS(Massnahmenplan!$C$5:$C$42,$A16,Massnahmenplan!$F$5:$F$42,"Überfällig") -> 1 | E16: =IFERROR(ROUND(AVERAGEIF(Massnahmenplan!$C$5:$C$42,$A16,Massnahmenplan!$G$5:$G$42),0),"") -> 33 | F16: =COUNTIF(Meilensteine!$D$5:$D$22,$A16) -> 2 | G16: =COUNTIFS(Meilensteine!$D$5:$D$22,$A16,Meilensteine!$I$5:$I$22,"Verzögert") -> 1
A17: WS3 IT | B17: =COUNTIF(Massnahmenplan!$C$5:$C$42,$A17) -> 7 | C17: =COUNTIFS(Massnahmenplan!$C$5:$C$42,$A17,Massnahmenplan!$F$5:$F$42,"Erledigt") -> 1 | D17: =COUNTIFS(Massnahmenplan!$C$5:$C$42,$A17,Massnahmenplan!$F$5:$F$42,"Überfällig") -> 1 | E17: =IFERROR(ROUND(AVERAGEIF(Massnahmenplan!$C$5:$C$42,$A17,Massnahmenplan!$G$5:$G$42),0),"") -> 59 | F17: =COUNTIF(Meilensteine!$D$5:$D$22,$A17) -> 2 | G17: =COUNTIFS(Meilensteine!$D$5:$D$22,$A17,Meilensteine!$I$5:$I$22,"Verzögert") -> 1
A18: WS4 Personal | B18: =COUNTIF(Massnahmenplan!$C$5:$C$42,$A18) -> 6 | C18: =COUNTIFS(Massnahmenplan!$C$5:$C$42,$A18,Massnahmenplan!$F$5:$F$42,"Erledigt") -> 0 | D18: =COUNTIFS(Massnahmenplan!$C$5:$C$42,$A18,Massnahmenplan!$F$5:$F$42,"Überfällig") -> 0 | E18: =IFERROR(ROUND(AVERAGEIF(Massnahmenplan!$C$5:$C$42,$A18,Massnahmenplan!$G$5:$G$42),0),"") -> 49 | F18: =COUNTIF(Meilensteine!$D$5:$D$22,$A18) -> 4 | G18: =COUNTIFS(Meilensteine!$D$5:$D$22,$A18,Meilensteine!$I$5:$I$22,"Verzögert") -> 1
A19: WS5 Lieferkette | B19: =COUNTIF(Massnahmenplan!$C$5:$C$42,$A19) -> 4 | C19: =COUNTIFS(Massnahmenplan!$C$5:$C$42,$A19,Massnahmenplan!$F$5:$F$42,"Erledigt") -> 0 | D19: =COUNTIFS(Massnahmenplan!$C$5:$C$42,$A19,Massnahmenplan!$F$5:$F$42,"Überfällig") -> 0 | E19: =IFERROR(ROUND(AVERAGEIF(Massnahmenplan!$C$5:$C$42,$A19,Massnahmenplan!$G$5:$G$42),0),"") -> 37 | F19: =COUNTIF(Meilensteine!$D$5:$D$22,$A19) -> 2 | G19: =COUNTIFS(Meilensteine!$D$5:$D$22,$A19,Meilensteine!$I$5:$I$22,"Verzögert") -> 0
A20: WS6 Vertrieb und Marketing | B20: =COUNTIF(Massnahmenplan!$C$5:$C$42,$A20) -> 5 | C20: =COUNTIFS(Massnahmenplan!$C$5:$C$42,$A20,Massnahmenplan!$F$5:$F$42,"Erledigt") -> 1 | D20: =COUNTIFS(Massnahmenplan!$C$5:$C$42,$A20,Massnahmenplan!$F$5:$F$42,"Überfällig") -> 0 | E20: =IFERROR(ROUND(AVERAGEIF(Massnahmenplan!$C$5:$C$42,$A20,Massnahmenplan!$G$5:$G$42),0),"") -> 47 | F20: =COUNTIF(Meilensteine!$D$5:$D$22,$A20) -> 4 | G20: =COUNTIFS(Meilensteine!$D$5:$D$22,$A20,Meilensteine!$I$5:$I$22,"Verzögert") -> 0
A21: WS7 Immobilien | B21: =COUNTIF(Massnahmenplan!$C$5:$C$42,$A21) -> 3 | C21: =COUNTIFS(Massnahmenplan!$C$5:$C$42,$A21,Massnahmenplan!$F$5:$F$42,"Erledigt") -> 0 | D21: =COUNTIFS(Massnahmenplan!$C$5:$C$42,$A21,Massnahmenplan!$F$5:$F$42,"Überfällig") -> 0 | E21: =IFERROR(ROUND(AVERAGEIF(Massnahmenplan!$C$5:$C$42,$A21,Massnahmenplan!$G$5:$G$42),0),"") -> 48 | F21: =COUNTIF(Meilensteine!$D$5:$D$22,$A21) -> 1 | G21: =COUNTIFS(Meilensteine!$D$5:$D$22,$A21,Meilensteine!$I$5:$I$22,"Verzögert") -> 0
A23: Meilensteine gesamt
A24: Meilensteine gesamt | B24: =COUNTA(Meilensteine!$B$5:$B$22) -> 18
A25: davon gate-relevant | B25: =COUNTIF(Meilensteine!$J$5:$J$22,"Ja") -> 13
A26: davon verzoegert | B26: =COUNTIF(Meilensteine!$I$5:$I$22,"Verzögert") -> 3
A27: groesste Abweichung in Tagen | B27: =MAX(Meilensteine!$H$5:$H$22) -> 14
A28: Tage bis Day 100 | B28: =DATE(2016,12,16)-DATE(2016,9,29) -> 78
